<?xml version="1.0"?>
<robot name="my_robot">

  <!-- ********  FIXED GROUND  ******** -->
  <link name="fixed_ground">
    <visual>
      <geometry><mesh filename="mesh/fixed_ground.stl" scale="0.001 0.001 0.001"/></geometry>
    </visual>
    <collision>
      <geometry><mesh filename="mesh/fixed_ground.stl" scale="0.001 0.001 0.001"/></geometry>
    </collision>
    <inertial>
      <mass value="0.001"/>
      <inertia ixx="0.001" ixy="0.0" ixz="0.0" iyy="0.001" iyz="0.0" izz="0.001"/>
    </inertial>
  </link>

  <!-- ********  BASE  ******** -->
  <link name="base">
    <visual>
      <geometry><mesh filename="mesh/base.stl" scale="0.001 0.001 0.001"/></geometry>
    </visual>
    <collision>
      <geometry><mesh filename="../mesh/base.stl" scale="0.001 0.001 0.001"/></geometry>
    </collision>
    <inertial>
      <mass value="0.8"/>
      <inertia ixx="0.001" ixy="0.0" ixz="0.0" iyy="0.001" iyz="0.0" izz="0.001"/>
    </inertial>
  </link>

  <joint name="joint0" type="revolute">
    <parent link="fixed_ground"/>
    <child link="base"/>
    <origin xyz="0 0 0.025" rpy="0 0 0"/>
    <axis xyz="0 0 1"/>
    <limit lower="-3.14" upper="3.14" effort="10" velocity="5"/>
  </joint>

  <!-- ********  LINK1  ******** -->
  <link name="link1">
    <visual>
      <geometry><mesh filename="../mesh/link1.stl" scale="0.001 0.001 0.001"/></geometry>
    </visual>
    <collision>
      <geometry><mesh filename="../mesh/link1.stl" scale="0.001 0.001 0.001"/></geometry>
    </collision>
    <inertial>
      <mass value="0.5"/>
      <inertia ixx="0.001" ixy="0.0" ixz="0.0" iyy="0.001" iyz="0.0" izz="0.001"/>
    </inertial>
  </link>

  <joint name="joint1" type="revolute">
    <parent link="base"/>
    <child link="link1"/>
    <origin xyz="0 0 0.076" rpy="0 0 0"/>
    <axis xyz="0 1 0"/>
    <limit lower="-3.14" upper="3.14" effort="10" velocity="5"/>
  </joint>

  <!-- ********  LINK2  ******** -->
  <link name="link2">
    <visual>
      <geometry><mesh filename="../mesh/link2.stl" scale="0.001 0.001 0.001"/></geometry>
    </visual>
    <collision>
      <geometry><mesh filename="../mesh/link2.stl" scale="0.001 0.001 0.001"/></geometry>
    </collision>
    <inertial>
      <mass value="0.4"/>
      <inertia ixx="0.001" ixy="0.0" ixz="0.0" iyy="0.001" iyz="0.0" izz="0.001"/>
    </inertial>
  </link>

  <joint name="joint2" type="revolute">
    <parent link="link1"/>
    <child link="link2"/>
    <origin xyz="0 0 0.4" rpy="0 0 0"/>
    <axis xyz="0 1 0"/>
    <limit lower="-3.14" upper="3.14" effort="10" velocity="5"/>
  </joint>

  <!-- ********  LINK3  ******** -->
  <link name="link3">
    <visual>
      <geometry><mesh filename="../mesh/link3.stl" scale="0.001 0.001 0.001"/></geometry>
    </visual>
    <collision>
      <geometry><mesh filename="../mesh/link3.stl" scale="0.001 0.001 0.001"/></geometry>
    </collision>
    <inertial>
      <mass value="0.3"/>
      <inertia ixx="0.001" ixy="0.0" ixz="0.0" iyy="0.001" iyz="0.0" izz="0.001"/>
    </inertial>
  </link>

  <joint name="joint3" type="revolute">
    <parent link="link2"/>
    <child link="link3"/>
    <origin xyz="0.18 0 0" rpy="0 0 0"/>
    <axis xyz="1 0 0"/>
    <limit lower="-3.14" upper="3.14" effort="10" velocity="5"/>
  </joint>

  <!-- ********  LINK4  ******** -->
  <link name="link4">
    <visual>
      <geometry><mesh filename="../mesh/link4.stl" scale="0.001 0.001 0.001"/></geometry>
    </visual>
    <collision>
      <geometry><mesh filename="../mesh/link4.stl" scale="0.001 0.001 0.001"/></geometry>
    </collision>
    <inertial>
      <mass value="0.2"/>
      <inertia ixx="0.001" ixy="0.0" ixz="0.0" iyy="0.001" iyz="0.0" izz="0.001"/>
    </inertial>
  </link>

  <joint name="joint4" type="revolute">
    <parent link="link3"/>
    <child link="link4"/>
    <origin xyz="0.135 0 0" rpy="0 0 0"/>
    <axis xyz="0 1 0"/>
    <limit lower="-3.14" upper="3.14" effort="10" velocity="5"/>
  </joint>

  <!-- ********  LINK5  ******** -->
  <link name="link5">
    <visual>
      <geometry><mesh filename="mesh/link5.stl" scale="0.001 0.001 0.001"/></geometry>
    </visual>
    <collision>
      <geometry><mesh filename="mesh/link5.stl" scale="0.001 0.001 0.001"/></geometry>
    </collision>
    <inertial>
      <mass value="0.15"/>
      <inertia ixx="0.001" ixy="0.0" ixz="0.0" iyy="0.001" iyz="0.0" izz="0.001"/>
    </inertial>
  </link>

  <joint name="joint5" type="revolute">
    <parent link="link4"/>
    <child link="link5"/>
    <origin xyz="0.05 0 0" rpy="0 0 0"/>
    <axis xyz="1 0 0"/>
    <limit lower="-3.14" upper="3.14" effort="10" velocity="5"/>
  </joint>

</robot>
