<?xml version="1.0"?>
<!-- 
  Default Robot URDF Template
  Replace with your actual robot URDF or modify this template
  
  Key Parameters to Update:
  - STL file paths (currently pointing to assets/stl_models/)
  - Link lengths and dimensions
  - Link masses (for physics simulation)
  - Joint limits (min/max angles in radians)
  - Joint axes (rotation direction)
  
  Coordinate Convention:
  - X: Forward
  - Y: Sideways (left positive)
  - Z: Up (gravity is -Z)
  
  STL Scale: 0.001 0.001 0.001 (converts mm to meters if STL is in mm)
-->

<?xml version="1.0"?>
<robot name="robotic_arm">
  
  <!-- ========================= BASE LINK ========================= -->
  <link name="base_link">
    <inertial>
      <mass value="5.0"/>
      <origin xyz="0 0 0.05" rpy="0 0 0"/>
      <inertia ixx="0.1" ixy="0.0" ixz="0.0" iyy="0.1" iyz="0.0" izz="0.05"/>
    </inertial>
    
    <visual>
      <origin xyz="0 0 0" rpy="0 0 0"/>
      <geometry>
        <!-- CUSTOMIZE: Point to your base STL file -->
        <mesh filename="package://robot_nn_ik/assets/stl_models/base.stl" scale="0.001 0.001 0.001"/>
        <!-- Or use primitive geometry if no STL: -->
        <!-- <box size="0.2 0.2 0.1"/> -->
      </geometry>
      <material name="base_material">
        <color rgba="0.5 0.5 0.5 1.0"/>
      </material>
    </visual>
    
    <collision>
      <origin xyz="0 0 0" rpy="0 0 0"/>
      <geometry>
        <box size="0.2 0.2 0.1"/>
      </geometry>
    </collision>
  </link>

  <!-- ========================= LINK 1 ========================= -->
  <link name="link1">
    <inertial>
      <mass value="2.0"/>
      <origin xyz="0 0 0.15" rpy="0 0 0"/>
      <inertia ixx="0.02" ixy="0.0" ixz="0.0" iyy="0.02" iyz="0.0" izz="0.01"/>
    </inertial>
    
    <visual>
      <geometry>
        <!-- CUSTOMIZE: Use your link1 STL -->
        <mesh filename="package://robot_nn_ik/assets/stl_models/link1.stl" scale="0.001 0.001 0.001"/>
      </geometry>
      <material name="link1_material">
        <color rgba="0.7 0.7 0.7 1.0"/>
      </material>
    </visual>
    
    <collision>
      <geometry>
        <cylinder length="0.3" radius="0.04"/>
      </geometry>
    </collision>
  </link>

  <!-- JOINT 1: base_link to link1 (Revolute) -->
  <joint name="joint1" type="revolute">
    <parent link="base_link"/>
    <child link="link1"/>
    
    <!-- CUSTOMIZE: Adjust origin to match your robot -->
    <origin xyz="0 0 0.1" rpy="0 0 0"/>
    
    <!-- Rotation axis: Z for vertical rotation, X/Y for other directions -->
    <axis xyz="0 0 1"/>
    
    <!-- CUSTOMIZE: Set limits in radians (±180° = ±3.14159) -->
    <limit lower="-3.14159" upper="3.14159" effort="100" velocity="1.0"/>
    <dynamics friction="0.1" damping="0.1"/>
  </joint>

  <!-- ========================= LINK 2 ========================= -->
  <link name="link2">
    <inertial>
      <mass value="1.5"/>
      <origin xyz="0 0 0.175" rpy="0 0 0"/>
      <inertia ixx="0.015" ixy="0.0" ixz="0.0" iyy="0.015" iyz="0.0" izz="0.01"/>
    </inertial>
    
    <visual>
      <geometry>
        <mesh filename="package://robot_nn_ik/assets/stl_models/link2.stl" scale="0.001 0.001 0.001"/>
      </geometry>
      <material name="link2_material">
        <color rgba="0.7 0.7 0.7 1.0"/>
      </material>
    </visual>
    
    <collision>
      <geometry>
        <cylinder length="0.35" radius="0.035"/>
      </geometry>
    </collision>
  </link>

  <joint name="joint2" type="revolute">
    <parent link="link1"/>
    <child link="link2"/>
    <origin xyz="0 0 0.3" rpy="0 0 0"/>
    <!-- CUSTOMIZE: Change axis if needed (e.g., "1 0 0" for X rotation) -->
    <axis xyz="0 1 0"/>
    <limit lower="-3.14159" upper="3.14159" effort="80" velocity="1.0"/>
    <dynamics friction="0.1" damping="0.1"/>
  </joint>

  <!-- ========================= LINK 3 ========================= -->
  <link name="link3">
    <inertial>
      <mass value="1.0"/>
      <origin xyz="0 0 0.15" rpy="0 0 0"/>
      <inertia ixx="0.01" ixy="0.0" ixz="0.0" iyy="0.01" iyz="0.0" izz="0.008"/>
    </inertial>
    
    <visual>
      <geometry>
        <mesh filename="package://robot_nn_ik/assets/stl_models/link3.stl" scale="0.001 0.001 0.001"/>
      </geometry>
      <material name="link3_material">
        <color rgba="0.7 0.7 0.7 1.0"/>
      </material>
    </visual>
    
    <collision>
      <geometry>
        <cylinder length="0.3" radius="0.03"/>
      </geometry>
    </collision>
  </link>

  <joint name="joint3" type="revolute">
    <parent link="link2"/>
    <child link="link3"/>
    <origin xyz="0 0 0.35" rpy="0 0 0"/>
    <axis xyz="0 1 0"/>
    <limit lower="-3.14159" upper="3.14159" effort="60" velocity="1.0"/>
    <dynamics friction="0.1" damping="0.1"/>
  </joint>

  <!-- ========================= LINK 4 ========================= -->
  <link name="link4">
    <inertial>
      <mass value="0.8"/>
      <origin xyz="0 0 0.05" rpy="0 0 0"/>
      <inertia ixx="0.005" ixy="0.0" ixz="0.0" iyy="0.005" iyz="0.0" izz="0.005"/>
    </inertial>
    
    <visual>
      <geometry>
        <mesh filename="package://robot_nn_ik/assets/stl_models/link4.stl" scale="0.001 0.001 0.001"/>
      </geometry>
      <material name="link4_material">
        <color rgba="0.7 0.7 0.7 1.0"/>
      </material>
    </visual>
    
    <collision>
      <geometry>
        <cylinder length="0.1" radius="0.025"/>
      </geometry>
    </collision>
  </link>

  <joint name="joint4" type="revolute">
    <parent link="link3"/>
    <child link="link4"/>
    <origin xyz="0 0 0.3" rpy="0 0 0"/>
    <axis xyz="1 0 0"/>
    <limit lower="-3.14159" upper="3.14159" effort="40" velocity="1.5"/>
    <dynamics friction="0.05" damping="0.05"/>
  </joint>

  <!-- ========================= LINK 5 ========================= -->
  <link name="link5">
    <inertial>
      <mass value="0.6"/>
      <origin xyz="0 0 0.05" rpy="0 0 0"/>
      <inertia ixx="0.004" ixy="0.0" ixz="0.0" iyy="0.004" iyz="0.0" izz="0.004"/>
    </inertial>
    
    <visual>
      <geometry>
        <mesh filename="package://robot_nn_ik/assets/stl_models/link5.stl" scale="0.001 0.001 0.001"/>
      </geometry>
      <material name="link5_material">
        <color rgba="0.7 0.7 0.7 1.0"/>
      </material>
    </visual>
    
    <collision>
      <geometry>
        <cylinder length="0.1" radius="0.02"/>
      </geometry>
    </collision>
  </link>

  <joint name="joint5" type="revolute">
    <parent link="link4"/>
    <child link="link5"/>
    <origin xyz="0 0 0.1" rpy="0 0 0"/>
    <axis xyz="0 1 0"/>
    <limit lower="-3.14159" upper="3.14159" effort="30" velocity="1.5"/>
    <dynamics friction="0.05" damping="0.05"/>
  </joint>

  <!-- ========================= LINK 6 (End Effector) ========================= -->
  <link name="link6">
    <inertial>
      <mass value="0.5"/>
      <origin xyz="0 0 0.05" rpy="0 0 0"/>
      <inertia ixx="0.003" ixy="0.0" ixz="0.0" iyy="0.003" iyz="0.0" izz="0.003"/>
    </inertial>
    
    <visual>
      <geometry>
        <mesh filename="package://robot_nn_ik/assets/stl_models/link6.stl" scale="0.001 0.001 0.001"/>
      </geometry>
      <material name="link6_material">
        <color rgba="0.9 0.2 0.2 1.0"/>
      </material>
    </visual>
    
    <collision>
      <geometry>
        <sphere radius="0.02"/>
      </geometry>
    </collision>
  </link>

  <joint name="joint6" type="revolute">
    <parent link="link5"/>
    <child link="link6"/>
    <origin xyz="0 0 0.1" rpy="0 0 0"/>
    <axis xyz="1 0 0"/>
    <limit lower="-3.14159" upper="3.14159" effort="20" velocity="2.0"/>
    <dynamics friction="0.02" damping="0.02"/>
  </joint>

  <!-- ========================= TRANSMISSION (For Gazebo Control) ========================= -->
  <!-- These define how joints are controlled in Gazebo -->

  <transmission name="tran1">
    <type>transmission_interface/SimpleTransmission</type>
    <joint name="joint1">
      <hardwareInterface>hardware_interface/PositionJointInterface</hardwareInterface>
    </joint>
    <actuator name="motor1">
      <mechanicalReduction>1</mechanicalReduction>
      <hardwareInterface>hardware_interface/PositionJointInterface</hardwareInterface>
    </actuator>
  </transmission>

  <transmission name="tran2">
    <type>transmission_interface/SimpleTransmission</type>
    <joint name="joint2">
      <hardwareInterface>hardware_interface/PositionJointInterface</hardwareInterface>
    </joint>
    <actuator name="motor2">
      <mechanicalReduction>1</mechanicalReduction>
      <hardwareInterface>hardware_interface/PositionJointInterface</hardwareInterface>
    </actuator>
  </transmission>

  <transmission name="tran3">
    <type>transmission_interface/SimpleTransmission</type>
    <joint name="joint3">
      <hardwareInterface>hardware_interface/PositionJointInterface</hardwareInterface>
    </joint>
    <actuator name="motor3">
      <mechanicalReduction>1</mechanicalReduction>
      <hardwareInterface>hardware_interface/PositionJointInterface</hardwareInterface>
    </actuator>
  </transmission>

  <transmission name="tran4">
    <type>transmission_interface/SimpleTransmission</type>
    <joint name="joint4">
      <hardwareInterface>hardware_interface/PositionJointInterface</hardwareInterface>
    </joint>
    <actuator name="motor4">
      <mechanicalReduction>1</mechanicalReduction>
      <hardwareInterface>hardware_interface/PositionJointInterface</hardwareInterface>
    </actuator>
  </transmission>

  <transmission name="tran5">
    <type>transmission_interface/SimpleTransmission</type>
    <joint name="joint5">
      <hardwareInterface>hardware_interface/PositionJointInterface</hardwareInterface>
    </joint>
    <actuator name="motor5">
      <mechanicalReduction>1</mechanicalReduction>
      <hardwareInterface>hardware_interface/PositionJointInterface</hardwareInterface>
    </actuator>
  </transmission>

  <transmission name="tran6">
    <type>transmission_interface/SimpleTransmission</type>
    <joint name="joint6">
      <hardwareInterface>hardware_interface/PositionJointInterface</hardwareInterface>
    </joint>
    <actuator name="motor6">
      <mechanicalReduction>1</mechanicalReduction>
      <hardwareInterface>hardware_interface/PositionJointInterface</hardwareInterface>
    </actuator>
  </transmission>

  <!-- ========================= GAZEBO PLUGIN ========================= -->
  <!-- ROS Control plugin for Gazebo -->

  <gazebo>
    <plugin name="gazebo_ros_control" filename="libgazebo_ros_control.so">
      <robotNamespace>/robotic_arm</robotNamespace>
    </plugin>
  </gazebo>

  <!-- ========================= LINK COLORS ========================= -->
  <gazebo reference="base_link">
    <material>Gazebo/Gray</material>
  </gazebo>

  <gazebo reference="link1">
    <material>Gazebo/Gray</material>
  </gazebo>

  <gazebo reference="link2">
    <material>Gazebo/Gray</material>
  </gazebo>

  <gazebo reference="link3">
    <material>Gazebo/Gray</material>
  </gazebo>

  <gazebo reference="link4">
    <material>Gazebo/Gray</material>
  </gazebo>

  <gazebo reference="link5">
    <material>Gazebo/Gray</material>
  </gazebo>

  <gazebo reference="link6">
    <material>Gazebo/Red</material>
  </gazebo>

</robot>
